Traceback (most recent call last):
  File "../generateParam/genParam.sage.py", line 82, in <module>
    load('https://bitbucket.org/malb/lwe-estimator/raw/HEAD/estimator.py')
  File "sage/structure/sage_object.pyx", line 1057, in sage.structure.sage_object.load (build/cythonized/sage/structure/sage_object.c:12879)
  File "/usr/lib/python2.7/dist-packages/sage/repl/load.py", line 211, in load
    filename = get_remote_file(filename, verbose=False)
  File "/usr/lib/python2.7/dist-packages/sage/misc/remote_file.py", line 48, in get_remote_file
    urlretrieve(filename, temp_name)
  File "/usr/lib/python2.7/urllib.py", line 98, in urlretrieve
    return opener.retrieve(url, filename, reporthook, data)
  File "/usr/lib/python2.7/urllib.py", line 245, in retrieve
    fp = self.open(url, data)
  File "/usr/lib/python2.7/urllib.py", line 213, in open
    return getattr(self, name)(url)
  File "/usr/lib/python2.7/urllib.py", line 443, in open_https
    h.endheaders(data)
  File "/usr/lib/python2.7/httplib.py", line 1038, in endheaders
    self._send_output(message_body)
  File "/usr/lib/python2.7/httplib.py", line 882, in _send_output
    self.send(msg)
  File "/usr/lib/python2.7/httplib.py", line 844, in send
    self.connect()
  File "/usr/lib/python2.7/httplib.py", line 1263, in connect
    server_hostname=server_hostname)
  File "/usr/lib/python2.7/ssl.py", line 369, in wrap_socket
    _context=self)
  File "/usr/lib/python2.7/ssl.py", line 617, in __init__
    self.do_handshake()
  File "/usr/lib/python2.7/ssl.py", line 846, in do_handshake
    self._sslobj.do_handshake()
IOError: [Errno socket error] [Errno 104] Connection reset by peer
